<?xml version="1.0" encoding="UTF-8"?>
<testsuite name="EventTest" tests="13" skipped="0" failures="0" errors="0" timestamp="2021-11-12T10:08:49" hostname="MacBook-Pro-do-Francisco-Bastos.local" time="0.073">
  <properties/>
  <testcase name="testToString()" classname="EventTest" time="0.046"/>
  <testcase name="getSuperDate()" classname="EventTest" time="0.002"/>
  <testcase name="getName()" classname="EventTest" time="0.001"/>
  <testcase name="insertPerson()" classname="EventTest" time="0.001"/>
  <testcase name="getSource()" classname="EventTest" time="0.002"/>
  <testcase name="testHashCode()" classname="EventTest" time="0.002"/>
  <testcase name="getPersonsInvolved()" classname="EventTest" time="0.001"/>
  <testcase name="testEquals()" classname="EventTest" time="0.001"/>
  <testcase name="getStandardEvents()" classname="EventTest" time="0.001"/>
  <testcase name="isSensitive()" classname="EventTest" time="0.002"/>
  <testcase name="impossibleEventTest()" classname="EventTest" time="0.001"/>
  <testcase name="getDescription()" classname="EventTest" time="0.001"/>
  <testcase name="getPlace()" classname="EventTest" time="0.001"/>
  <system-out><![CDATA[Do something after each test
Do something after each test
Do something after each test
It's ok to throw exception, 'cause there is already a person
Do something after each test
Do something after each test
Do something after each test
Do something after each test
Do something after each test
Do something after each test
Do something after each test
It should not create an event
Do something after each test
Do something after each test
Do something after each test
]]></system-out>
  <system-err><![CDATA[]]></system-err>
</testsuite>
